<?xml version="1.0" encoding="utf-8"?>
<!-- This URDF was automatically created by SolidWorks to URDF Exporter! Originally created by
Stephen Brawner (brawner@gmail.com) 
     Commit Version: 1.6.0-4-g7f85cfe  Build Version: 1.6.7995.38578
     For more information, please see http://wiki.ros.org/sw_urdf_exporter -->
<robot name="ranger_mini">

  <material name="silver_grey">
    <color rgba="0.792156862745098 0.819607843137255 0.933333333333333 1" />
  </material>

  <link name="base_link">
    <inertial>
      <origin xyz="-0.0242698272228022 -0.0030308024613212 0.0544267444673498" rpy="0 0 0" />
      <mass value="0.162715996120322" />
      <inertia ixx="0.000723700192916944" ixy="-1.55745142682799E-08" ixz="-3.42378773027466E-12"
        iyy="0.000744046536331603" iyz="2.24935144207573E-07" izz="2.14412578189702E-05" />
    </inertial>
    <visual>
      <origin xyz="0 0 0" rpy="0 0 0" />
      <geometry>
        <mesh filename="package://ranger_mini_v2/meshes/base_link.stl" scale="0.001 0.001 0.001" />
      </geometry>
      <material name="silver_grey" />
    </visual>
    <collision>
      <origin xyz="0 0 0" rpy="0 0 0" />
      <geometry>
        <mesh filename="package://ranger_mini_v2/meshes/base_link.stl" scale="0.001 0.001 0.001" />
      </geometry>
    </collision>
  </link>

  <!-- Front Right Wheel Section -->
  <link name="fr_wheel_mount_link">
    <inertial>
      <origin xyz="0.0 0.0 0.0" />
      <mass value="1" />
      <inertia ixx="0.01" ixy="0.0" ixz="0.0" iyy="0.01" iyz="0.0" izz="0.01" />
    </inertial>
    <visual>
      <origin xyz="-0.24 0.18 0.1" rpy="0 0 0" />
      <geometry>
        <mesh filename="package://ranger_mini_v2/meshes/Wheel_Mount_FR_1.stl"
          scale="0.001 0.001 0.001" />
      </geometry>
      <material name="silver_grey" />
    </visual>
  </link>
  <joint name="fr_wheel_mount" type="revolute">
    <origin xyz="0.24 -0.18 -0.1" rpy="0 0 0" />
    <parent link="base_link" />
    <child link="fr_wheel_mount_link" />
    <axis xyz="0 0 1" rpy="0 0 0" />
    <limit effort="5" velocity="6.28" lower="-2.1" upper="2.1" />
  </joint>

  <link name="fr_Link">
    <inertial>
      <origin xyz="1.8493E-05 1.2713E-06 0.043679" rpy="0 0 0" />
      <mass value="2.2786" />
      <inertia ixx="0.0063625" ixy="-1.0581E-07" ixz="-4.0831E-07" iyy="0.006363" iyz="-3.4944E-08"
        izz="0.010465" />
    </inertial>
    <visual>
      <origin xyz="-0.245 0.18 0.22" rpy="0 0 0" />
      <geometry>
        <mesh filename="package://ranger_mini_v2/meshes/Wheel_FR_1.stl" scale="0.001 0.001 0.001" />
      </geometry>
      <material name="silver_grey" />
    </visual>
    <collision>
      <origin xyz="-0.245 0.18 0.22" rpy="0 0 0" />
      <geometry>
        <mesh filename="package://ranger_mini_v2/meshes/Wheel_FR_1.stl" scale="0.001 0.001 0.001" />
      </geometry>
    </collision>
  </link>
  <joint name="fr_joint" type="continuous">
    <origin xyz="0 -0.02 -0.12" rpy="0 0 0" />
    <parent link="fr_wheel_mount_link" />
    <child link="fr_Link" />
    <axis xyz="0 1 0" />
  </joint>

  <!-- Front Left Wheel Section -->
  <link name="fl_wheel_mount_link">
    <inertial>
      <origin xyz="0.0 0.0 0.0" />
      <mass value="1" />
      <inertia ixx="0.01" ixy="0.0" ixz="0.0" iyy="0.01" iyz="0.0" izz="0.01" />
    </inertial>
    <visual>
      <origin xyz="-0.24 -0.18 0.1" rpy="0 0 0" />
      <geometry>
        <mesh filename="package://ranger_mini_v2/meshes/Wheel_Mount_FL_1.stl"
          scale="0.001 0.001 0.001" />
      </geometry>
      <material name="silver_grey" />
    </visual>
  </link>
  <joint name="fl_wheel_mount" type="revolute">
    <origin xyz="0.24 0.18 -0.1" rpy="0 0 0" />
    <parent link="base_link" />
    <child link="fl_wheel_mount_link" />
    <axis xyz="0 0 1" rpy="0 0 0" />
    <limit effort="5" velocity="6.28" lower="-2.1" upper="2.1" />
  </joint>
  <link name="fl_Link">
    <inertial>
      <origin xyz="-0.0017956 -9.6304E-08 0.043642" rpy="0 0 0" />
      <mass value="2.2786" />
      <inertia ixx="0.0063695" ixy="-2.1067E-08" ixz="-0.00016867" iyy="0.006363" iyz="-1.0301E-08"
        izz="0.010458" />
    </inertial>
    <visual>
      <origin xyz="-0.245 -0.18 0.22" rpy="0 0 0" />
      <geometry>
        <mesh filename="package://ranger_mini_v2/meshes/Wheel_FL_1.stl" scale="0.001 0.001 0.001" />
      </geometry>
      <material name="silver_grey" />
    </visual>
    <collision>
      <origin xyz="-0.245 -0.18 0.22" rpy="0 0 0" />
      <geometry>
        <mesh filename="package://ranger_mini_v2/meshes/Wheel_FL_1.stl" scale="0.001 0.001 0.001" />
      </geometry>
    </collision>
  </link>
  <joint name="fl_joint" type="continuous">
    <origin xyz="0 0.02 -0.12" rpy="0 0 0" />
    <parent link="fl_wheel_mount_link" />
    <child link="fl_Link" />
    <axis xyz="0 1 0" />
  </joint>

  <!-- Rear Right Wheel Section -->
  <link name="rr_wheel_mount_link">
    <inertial>
      <origin xyz="0.0 0.0 0.0" />
      <mass value="1" />
      <inertia ixx="0.01" ixy="0.0" ixz="0.0" iyy="0.01" iyz="0.0" izz="0.01" />
    </inertial>
    <visual>
      <origin xyz="0.24 0.18 0.1" rpy="0 0 0" />
      <geometry>
        <mesh filename="package://ranger_mini_v2/meshes/Wheel_Mount_RR_1.stl"
          scale="0.001 0.001 0.001" />
      </geometry>
      <material name="silver_grey" />
    </visual>
  </link>
  <joint name="rr_wheel_mount" type="revolute">
    <origin xyz="-0.24 -0.18 -0.1" rpy="0 0 0" />
    <parent link="base_link" />
    <child link="rr_wheel_mount_link" />
    <axis xyz="0 0 1" rpy="0 0 0" />
    <limit effort="5" velocity="6.28" lower="-2.1" upper="2.1" />
  </joint>
  <link name="rr_Link">
    <inertial>
      <origin xyz="-0.00017093 6.1255E-08 0.043678" rpy="0 0 0" />
      <mass value="2.2786" />
      <inertia ixx="0.0063627" ixy="-2.1069E-08" ixz="-1.587E-05" iyy="0.006363" iyz="9.3201E-09"
        izz="0.010465" />
    </inertial>
    <visual>
      <origin xyz="0.245 0.18 0.224" rpy="0 -0.01 0" />
      <geometry>
        <mesh filename="package://ranger_mini_v2/meshes/Wheel_RR_1.stl" scale="0.001 0.001 0.001" />
      </geometry>
      <material name="silver_grey" />
    </visual>
    <collision>
      <origin xyz="0.245 0.18 0.224" rpy="0 -0.01 0" />
      <geometry>
        <mesh filename="package://ranger_mini_v2/meshes/Wheel_RR_1.stl" scale="0.001 0.001 0.001" />
      </geometry>
    </collision>
  </link>
  <joint name="rr_joint" type="continuous">
    <origin xyz="0 -0.02 -0.12" rpy="0 0 0" />
    <parent link="rr_wheel_mount_link" />
    <child link="rr_Link" />
    <axis xyz="0 1 0" />
  </joint>

  <!-- Rear Left Wheel Section -->
  <link name="rl_wheel_mount_link">
    <inertial>
      <origin xyz="0.0 0.0 0.0" />
      <mass value="1" />
      <inertia ixx="0.01" ixy="0.0" ixz="0.0" iyy="0.01" iyz="0.0" izz="0.01" />
    </inertial>
    <visual>
      <origin xyz="0.24 -0.18 0.1" rpy="0 0 0" />
      <geometry>
        <mesh filename="package://ranger_mini_v2/meshes/Wheel_Mount_RL_1.stl"
          scale="0.001 0.001 0.001" />
      </geometry>
      <material name="silver_grey" />
    </visual>
  </link>
  <joint name="rl_wheel_mount" type="revolute">
    <origin xyz="-0.24 0.18 -0.1" rpy="0 0 0" />
    <parent link="base_link" />
    <child link="rl_wheel_mount_link" />
    <axis xyz="0 0 1" rpy="0 0 0" />
    <limit effort="5" velocity="6.28" lower="-2.1" upper="2.1" />
  </joint>
  <link name="rl_Link">
    <inertial>
      <origin xyz="-0.0011575 -4.8644E-06 0.043663" rpy="0 0 0" />
      <mass value="2.2786" />
      <inertia ixx="0.0063656" ixy="-8.1498E-08" ixz="-0.00011049" iyy="0.006363" iyz="6.6847E-08"
        izz="0.010462" />
    </inertial>
    <visual>
      <origin xyz="0.245 -0.18 0.22" rpy="0 0 0" />
      <geometry>
        <mesh filename="package://ranger_mini_v2/meshes/Wheel_RL_1.stl" scale="0.001 0.001 0.001" />
      </geometry>
      <material name="silver_grey" />
    </visual>
    <collision>
      <origin xyz="0.245 -0.18 0.22" rpy="0 0 0" />
      <geometry>
        <mesh filename="package://ranger_mini_v2/meshes/Wheel_RL_1.stl" scale="0.001 0.001 0.001" />
      </geometry>
    </collision>
  </link>
  <joint name="rl_joint" type="continuous">
    <origin xyz="0 0.02 -0.12" rpy="0 0 0" />
    <parent link="rl_wheel_mount_link" />
    <child link="rl_Link" />
    <axis xyz="0 1 0" />
  </joint>
</robot>